Workbook
Name IQ_CH: 110000
Name IQ_CQ: 5000
Name IQ_CY: 10000
Name IQ_DAILY: 500000
Name IQ_FH: 100000
Name IQ_FQ: 500
Name IQ_FY: 1000
Name IQ_LTM: 2000
Name IQ_MONTH: 15000
Name IQ_NTM: 6000
Name IQ_WEEK: 50000
Name IQ_YTD: 3000

Sheet <intro>

Sheet MSCI Europe Net Index EUR End o
A1: MSCI Europe Net Index EUR End of Day | Index Constituents Analysis 30-Nov-2020 10:09
A3: Index Constituents Analysis
A4: Report: Index Constituents & Weights
A5: 1 - 434 of 434
A6: Name | B6: RIC | C6: Open | D6: Ccy | E6: Foreign Inclusion Factor | F6: Domestic Inclusion Factor | G6: Index Shares | H6: Weight % | I6: Mcap (USD) | J6: ISIN | K6: Ticker
A7: Telecom Italia SpA | B7: TLITn.MI | C7: 0.4287 | D7: EUR | E7: 1 | F7: 1 | G7: 6027791699 | H7: 0.032487699 | I7: 3.087629e+09
A8: Metro AG | B8: B4B.DE | C8: 7.86 | D8: EUR | E8: 0.5 | F8: 0.5 | G8: 180060868 | H8: 0.017792998 | I8: 3.3820908e+09
A9: SES SA | B9: SESFd.PA | C9: 7.9 | D9: EUR | E9: 1 | F9: 1 | G9: 383457600 | H9: 0.0380848 | I9: 3.6195771e+09
A10: Bayerische Motoren Werke AG | B10: BMWG_p.DE | C10: 55.5 | D10: EUR | E10: 1 | F10: 1 | G10: 56867304 | H10: 0.039679196 | I10: 3.7711083e+09
A11: Fuchs Petrolub SE | B11: FPEG_p.DE | C11: 48.26 | D11: EUR | E11: 1 | F11: 1 | G11: 69500000 | H11: 0.042167646 | I11: 4.0076105e+09
A12: Leonardo SpA | B12: LDOF.MI | C12: 5.986 | D12: EUR | E12: 0.7 | F12: 0.7 | G12: 4.0470528e+08 | H12: 0.030456698 | I12: 4.1351468e+09
A13: thyssenkrupp AG | B13: TKAG.DE | C13: 5.564 | D13: EUR | E13: 0.65 | F13: 0.65 | G13: 4.0464563e+08 | H13: 0.028305395 | I13: 4.1386815e+09
A14: Andritz AG | B14: ANDR.VI | C14: 34.94 | D14: EUR | E14: 0.7 | F14: 0.7 | G14: 72800000 | H14: 0.031978752 | I14: 4341798136
A15: Bankinter SA | B15: BKT.MC | C15: 4.174 | D15: EUR | E15: 0.75 | F15: 0.75 | G15: 6.7414962e+08 | H15: 0.03537659 | I15: 4.4829187e+09
A16: JCDecaux SA | B16: JCDX.PA | C16: 17.89 | D16: EUR | E16: 0.4 | F16: 0.4 | G16: 85161124 | H16: 0.019153977 | I16: 4.550982e+09
A17: Telenet Group Holding NV | B17: TNET.BR | C17: 35.06 | D17: EUR | E17: 0.4 | F17: 0.4 | G17: 45498778 | H17: 0.020054825 | I17: 4.7650235e+09
A18: Eurazeo SE | B18: EURA.PA | C18: 52 | D18: EUR | E18: 0.5 | F18: 0.5 | G18: 39314622 | H18: 0.025701867 | I18: 4.8854079e+09
... A440: Nestle SA | B440: NESN.S | C440: 102.3 | D440: CHF | E440: 1 | F440: 1 | G440: 2976000000 | H440: 3.5403795 | I440: 3.3647745e+11
A441: 1 - 434 of 434

Sheet STOXX 600
A1: =TODAY() -> 44263 | B1: Name | C1: Adj Price | D1: Max | E1: Min | F1: Var | G1: Var% | H1: Vol | I1: Hour | J1: ISIN | K1: Ticker
B2: 3I Group | C2: 1.147,50 | D2: 1.151,00 | E2: 1.126,50 | F2: 12 | G2: 0.0106 | H2: 1,16M | I2: 0.73263889
B3: A2A | C3: 1.426 | D3: 1.436 | E3: 1.386 | F3: 0.04 | G3: 0.0289 | H3: 12,78M | I3: 0.73292824
B4: AAK | C4: 186.1 | D4: 188.7 | E4: 185.2 | F4: -0.7 | G4: -0.0035 | H4: 502,63K | I4: 0.72905093
B5: Aalberts Industries | C5: 40.7 | D5: 40.74 | E5: 39.77 | F5: 1.36 | G5: 0.0346 | H5: 289,16K | I5: 0.73483796
B6: ABB | C6: 28.27 | D6: 28.27 | E6: 27.35 | F6: 1.21 | G6: 0.0447 | H6: 8,66M | I6: 0.73081019
B7: ABN AMRO | C7: 10.74 | D7: 10.75 | E7: 9.96 | F7: 0.9 | G7: 0.0915 | H7: 10,54M | I7: 0.73453704
B8: Accor | C8: 34.77 | D8: 35 | E8: 34.14 | F8: 0.64 | G8: 0.0188 | H8: 1,52M | I8: 0.73328704
B9: Ackermans en van Haaren | C9: 133.8 | D9: 135.8 | E9: 133.5 | F9: 0.9 | G9: 0.0068 | H9: 27,58K | I9: 0.73327546
B10: ACS | C10: 26.49 | D10: 26.62 | E10: 26.035 | F10: 0.36 | G10: 0.0138 | H10: 311,75K | I10: 0.73261574
B11: Adecco N | C11: 63.78 | D11: 63.78 | E11: 61.88 | F11: 1.92 | G11: 0.031 | H11: 845,38K | I11: 0.72959491
B12: Adidas | C12: 280.06 | D12: 282.06 | E12: 271.65 | F12: 7.86 | G12: 0.0289 | H12: 459,19K | I12: 0.72899306
B13: Admiral Group | C13: 2.932,0 | D13: 2.967,0 | E13: 2.879,0 | F13: -27 | G13: -0.0091 | H13: 606,71K | I13: 0.73263889
B14: ADO Properties SARL | C14: 23.64 | D14: 23.84 | E14: 23.16 | F14: 0.4 | G14: 0.0172 | H14: 179,47K | I14: 0.72847222
B15: Adyen | C15: 1.860,00 | D15: 1.868,00 | E15: 1.785,50 | F15: 46 | G15: 0.0254 | H15: 82,37K | I15: 0.73320602
B16: Aedifica | C16: 96.3 | D16: 97.9 | E16: 96.1 | F16: -0.9 | G16: -0.0093 | H16: 68,31K | I16: 0.73283565
B17: Aegon NV | C17: 4.273 | D17: 4.304 | E17: 4.096 | F17: 0.199 | G17: 0.0488 | H17: 15,78M | I17: 0.73454861
B18: Aena | C18: 145.9 | D18: 146.45 | E18: 141.3 | F18: 6.3 | G18: 0.0451 | H18: 72,94K | I18: 0.73258102
B19: Aeroports Paris | C19: 105.5 | D19: 108.1 | E19: 103.5 | F19: 0.5 | G19: 0.0048 | H19: 145,85K | I19: 0.73277778
B20: AF AB | C20: 236 | D20: 236 | E20: 231.6 | F20: 4.6 | G20: 0.0199 | H20: 181,62K | I20: 0.72905093
B21: Ageas SA | C21: 50.92 | D21: 51.12 | E21: 50.38 | F21: 0.66 | G21: 0.0131 | H21: 626,39K | I21: 0.73357639
B22: Aggreko | C22: 889 | D22: 897 | E22: 883.5 | F22: -6 | G22: -0.0067 | H22: 1,23M | I22: 0.73263889
B23: Ahold Delhaize | C23: 22.5 | D23: 22.59 | E23: 22.24 | F23: 0.01 | G23: 0.0004 | H23: 3,63M | I23: 0.73538194
B24: AIB | C24: 1.948 | D24: 1.951 | E24: 1.85 | F24: 0.083 | G24: 0.0445 | H24: 2,83M | I24: 0.72005787
B25: Air France KLM SA | C25: 5.32 | D25: 5.36 | E25: 5.19 | F25: 0.14 | G25: 0.0274 | H25: 4,15M | I25: 0.73381944
B26: Air Liquide | C26: 130.85 | D26: 131.45 | E26: 127.5 | F26: 3.4 | G26: 0.0267 | H26: 1,12M | I26: 0.7343287
B27: Airbus Group | C27: 100.52 | D27: 100.68 | E27: 96.27 | F27: 5.1 | G27: 0.0534 | H27: 2,65M | I27: 0.73274306
... B37: Alten | C37: 95.4 | D37: 97.85 | E37: 93.1 | F37: 3 | G37: 0.0325 | H37: 66,98K | I37: 0.73265046
B38: Altice | C38: 5.34 | D38: 5.35 | E38: 5.32 | F38: 0 | G38: 0 | H38: 0 | I38: 44222
B39: Amadeus | C39: 60.06 | D39: 61.46 | E39: 59.78 | F39: 0.89 | G39: 0.015 | H39: 512,60K | I39: 0.7287963
B40: Ambu B | C40: 256.5 | D40: 261.1 | E40: 253 | F40: 0.6 | G40: 0.0023 | H40: 637,48K | I40: 0.72222222
B41: Amplifon SpA | C41: 30.37 | D41: 30.49 | E41: 29.33 | F41: 0.33 | G41: 0.011 | H41: 1,11M | I41: 0.73275463
B42: AMS | C42: 19.25 | D42: 19.4 | E42: 18.77 | F42: 0.21 | G42: 0.0113 | H42: 2,50M | I42: 0.73042824
B43: Amundi | C43: 64.95 | D43: 65.1 | E43: 64.25 | F43: 0.35 | G43: 0.0054 | H43: 203,39K | I43: 0.73288194
B44: Andritz Ag | C44: 39.425 | D44: 39.455 | E44: 38.365 | F44: 0.8 | G44: 0.0207 | H44: 0 | I44: 0.7291088
B45: Anglo American | C45: 3.018,5 | D45: 3.020,0 | E45: 2.908,0 | F45: 105 | G45: 0.036 | H45: 2,71M | I45: 0.73263889
B46: Anheuser Busch Inbev | C46: 51.87 | D46: 51.92 | E46: 50.7 | F46: 1.4 | G46: 0.0277 | H46: 1,71M | I46: 0.73585648
B47: Antofagasta | C47: 1.763,00 | D47: 1.764,00 | E47: 1.694,50 | F47: 37 | G47: 0.0214 | H47: 1,27M | I47: 0.73263889
B48: ArcelorMittal | C48: 20.92 | D48: 20.92 | E48: 20.25 | F48: 0.93 | G48: 0.0466 | H48: 8,20M | I48: 0.73420139
B49: Argen-X | C49: 249.6 | D49: 250.8 | E49: 237.2 | F49: 10.6 | G49: 0.0444 | H49: 133,08K | I49: 0.73291667
...

Sheet timeSeries
A1: =_xll.Thomson.Reuters.AFOSpreadsheetFormulas.DSGRID(timeSeries!$A$2:$A$435,CONCATENATE("P;MV;DY;ISIN;EPS;WC05476;WC06001;WC03251;WC08001;WC18199;WC01001;WC08366;WC01250;WC02501;WC08301;WC08376;WC02999;WC03998;WC03255;WC08231;WC08221;CODON;ENERDP015;ENERDP018;ENERDP014;ENPIDP079;WC09803;WC09802;WC08416;WC08411;ENERDP024;ENERDP025;ENERDP096;E","NERDP023;ENERDP124;ENERO03V;VOL"),"2005","2018","M","RowHeader=true;ColHeader=true;Heading=true;Code=true;Curn=true;LatestFirstValue=true;SeriesMetaDataLink=true;DispSeriesDescription=false;YearlyTSFormat=false;QuarterlyTSFormat=false;Sym=RIC") -> #NAME?
A2: ='MSCI Europe Net Index EUR End o'!B7 -> TLITn.MI
A3: ='MSCI Europe Net Index EUR End o'!B8 -> B4B.DE
A4: ='MSCI Europe Net Index EUR End o'!B9 -> SESFd.PA
A5: ='MSCI Europe Net Index EUR End o'!B10 -> BMWG_p.DE
A6: ='MSCI Europe Net Index EUR End o'!B11 -> FPEG_p.DE
A7: ='MSCI Europe Net Index EUR End o'!B12 -> LDOF.MI
A8: ='MSCI Europe Net Index EUR End o'!B13 -> TKAG.DE
A9: ='MSCI Europe Net Index EUR End o'!B14 -> ANDR.VI
A10: ='MSCI Europe Net Index EUR End o'!B15 -> BKT.MC
A11: ='MSCI Europe Net Index EUR End o'!B16 -> JCDX.PA
A12: ='MSCI Europe Net Index EUR End o'!B17 -> TNET.BR
A13: ='MSCI Europe Net Index EUR End o'!B18 -> EURA.PA
... A16: ='MSCI Europe Net Index EUR End o'!B21 -> AER.N
A17: ='MSCI Europe Net Index EUR End o'!B22 -> ORNBV.HE | B17: =_xll.Thomson.Reuters.AFOSpreadsheetFormulas.DSGRID(timeSeries!$A$2:$A$435,CONCATENATE("P;MV;DY;ISIN;EPS;WC05476;WC06001;WC03251;WC08001;WC18199;WC01001;WC08366;WC01250;WC02501;WC08301;WC08376;WC02999;WC03998;WC03255;WC08231;WC08221;CODON;ENERDP015;ENERDP018;ENERDP014;ENPIDP079;WC09803;WC09802;WC08416;WC08411;ENERDP024;ENERDP025;ENERDP096;E","NERDP023;ENERDP124;ENERO03V;VOL"),"2005","2018","M","RowHeader=true;ColHeader=true;Heading=true;Code=true;Curn=true;LatestFirstValue=true;SeriesMetaDataLink=true;DispSeriesDescription=false;YearlyTSFormat=false;QuarterlyTSFormat=false;Sym=RIC") -> #NAME?
A18: ='MSCI Europe Net Index EUR End o'!B23 -> SBSTB.OL
A19: ='MSCI Europe Net Index EUR End o'!B24 -> FRAG.DE
A20: ='MSCI Europe Net Index EUR End o'!B25 -> PIRC.MI
A21: ='MSCI Europe Net Index EUR End o'!B26 -> INDUc.ST
A22: ='MSCI Europe Net Index EUR End o'!B27 -> ICAD.PA
A23: ='MSCI Europe Net Index EUR End o'!B28 -> DLGD.L
A24: ='MSCI Europe Net Index EUR End o'!B29 -> ATCA.AS
A25: ='MSCI Europe Net Index EUR End o'!B30 -> WRT1V.HE
A26: ='MSCI Europe Net Index EUR End o'!B31 -> UHRN.S
A27: ='MSCI Europe Net Index EUR End o'!B32 -> VOES.VI
A28: ='MSCI Europe Net Index EUR End o'!B33 -> JMAT.L
A29: ='MSCI Europe Net Index EUR End o'!B34 -> MAP.MC
... A435: ='MSCI Europe Net Index EUR End o'!B440 -> NESN.S
